Workbook

Sheet Bank_Data
A1: CustomerId | B1: CreditScore | C1: Geography | D1: Gender | E1: Age | F1: Tenure | G1: Balance | H1: NumOfProducts | I1: HasCrCard | J1: IsActiveMember | K1: EstimatedSalary | L1: Exited
A2: 100000 | B2: 697 | C2: France | D2: Female | E2: 41 | F2: 3 | G2: 117211.57 | H2: 2 | I2: 1 | J2: 0 | K2: 99383.53 | L2: 0
A3: 100001 | B3: 637 | C3: France | D3: Female | E3: 32 | F3: 9 | G3: 41718.91 | H3: 2 | I3: 1 | J3: 0 | K3: 20553.74 | L3: 0
A4: 100002 | B4: 712 | C4: Germany | D4: Male | E4: 43 | F4: 1 | G4: 138113.14 | H4: 1 | I4: 1 | J4: 1 | K4: 88487.09 | L4: 0
A5: 100003 | B5: 795 | C5: Germany | D5: Female | E5: 39 | F5: 1 | G5: 45150.61 | H5: 2 | I5: 0 | J5: 0 | K5: 120694.2 | L5: 1
A6: 100004 | B6: 628 | C6: France | D6: Female | E6: 33 | F6: 7 | G6: 27515.78 | H6: 2 | I6: 0 | J6: 1 | K6: 191328.05 | L6: 0
A7: 100005 | B7: 628 | C7: Spain | D7: Male | E7: 44 | F7: 0 | G7: 28898.41 | H7: 2 | I7: 1 | J7: 0 | K7: 110596.17 | L7: 0
A8: 100006 | B8: 800 | C8: France | D8: Female | E8: 57 | F8: 6 | G8: 0 | H8: 2 | I8: 1 | J8: 0 | K8: 166534.86 | L8: 0
A9: 100007 | B9: 723 | C9: Germany | D9: Male | E9: 37 | F9: 4 | G9: 105235.63 | H9: 3 | I9: 1 | J9: 0 | K9: 116218.61 | L9: 0
A10: 100008 | B10: 605 | C10: Germany | D10: Male | E10: 46 | F10: 10 | G10: 0 | H10: 2 | I10: 1 | J10: 1 | K10: 22545.23 | L10: 0
A11: 100009 | B11: 702 | C11: Spain | D11: Male | E11: 26 | F11: 7 | G11: 0 | H11: 1 | I11: 1 | J11: 1 | K11: 73276.53 | L11: 0
A12: 100010 | B12: 606 | C12: Germany | D12: Male | E12: 29 | F12: 0 | G12: 0 | H12: 2 | I12: 1 | J12: 1 | K12: 121476.66 | L12: 0
A13: 100011 | B13: 606 | C13: Spain | D13: Female | E13: 44 | F13: 10 | G13: 70663.68 | H13: 1 | I13: 0 | J13: 0 | K13: 190859.88 | L13: 0
... A1001: 100999 | B1001: 704 | C1001: France | D1001: Male | E1001: 33 | F1001: 9 | G1001: 60328.68 | H1001: 1 | I1001: 1 | J1001: 0 | K1001: 118254.82 | L1001: 0

Sheet Dashboard
A1: BANK CUSTOMER CHURN & RETENTION DASHBOARD
A3: TOTAL CUSTOMERS | C3: CHURNED CUSTOMERS | E3: CHURN RATE | G3: AVG BALANCE
A4: =COUNTA(Bank_Data!A2:A1001) | C4: =COUNTIF(Bank_Data!L2:L1001,1) | E4: =COUNTIF(Bank_Data!L2:L1001,1)/COUNTA(Bank_Data!L2:L1001) | G4: =AVERAGE(Bank_Data!G2:G1001)
A7: Geography | B7: Churn Rate | D7: Age | E7: Churn Rate | G7: Products | H7: Churn Rate | J7: Member Status | K7: Customers
A8: France | B8: =AVERAGEIF(Bank_Data!C2:C1001,A8,Bank_Data!L2:L1001) | D8: 18 | E8: =AVERAGEIF(Bank_Data!E2:E1001,D8,Bank_Data!L2:L1001) | G8: 1 | H8: =AVERAGEIF(Bank_Data!H2:H1001,G8,Bank_Data!L2:L1001) | J8: Active | K8: =COUNTIF(Bank_Data!J2:J1001,1)
A9: Germany | B9: =AVERAGEIF(Bank_Data!C2:C1001,A9,Bank_Data!L2:L1001) | D9: 19 | E9: =AVERAGEIF(Bank_Data!E2:E1001,D9,Bank_Data!L2:L1001) | G9: 2 | H9: =AVERAGEIF(Bank_Data!H2:H1001,G9,Bank_Data!L2:L1001) | J9: Inactive | K9: =COUNTIF(Bank_Data!J2:J1001,0)
A10: Spain | B10: =AVERAGEIF(Bank_Data!C2:C1001,A10,Bank_Data!L2:L1001) | D10: 20 | E10: =AVERAGEIF(Bank_Data!E2:E1001,D10,Bank_Data!L2:L1001) | G10: 3 | H10: =AVERAGEIF(Bank_Data!H2:H1001,G10,Bank_Data!L2:L1001)
D11: 21 | E11: =AVERAGEIF(Bank_Data!E2:E1001,D11,Bank_Data!L2:L1001) | G11: 4 | H11: =AVERAGEIF(Bank_Data!H2:H1001,G11,Bank_Data!L2:L1001)
D12: 22 | E12: =AVERAGEIF(Bank_Data!E2:E1001,D12,Bank_Data!L2:L1001)
D13: 23 | E13: =AVERAGEIF(Bank_Data!E2:E1001,D13,Bank_Data!L2:L1001)
D14: 24 | E14: =AVERAGEIF(Bank_Data!E2:E1001,D14,Bank_Data!L2:L1001)
D15: 25 | E15: =AVERAGEIF(Bank_Data!E2:E1001,D15,Bank_Data!L2:L1001)
D16: 26 | E16: =AVERAGEIF(Bank_Data!E2:E1001,D16,Bank_Data!L2:L1001)
D17: 27 | E17: =AVERAGEIF(Bank_Data!E2:E1001,D17,Bank_Data!L2:L1001)
D18: 28 | E18: =AVERAGEIF(Bank_Data!E2:E1001,D18,Bank_Data!L2:L1001)
D19: 29 | E19: =AVERAGEIF(Bank_Data!E2:E1001,D19,Bank_Data!L2:L1001)
D20: 30 | E20: =AVERAGEIF(Bank_Data!E2:E1001,D20,Bank_Data!L2:L1001)
D21: 31 | E21: =AVERAGEIF(Bank_Data!E2:E1001,D21,Bank_Data!L2:L1001)
D22: 32 | E22: =AVERAGEIF(Bank_Data!E2:E1001,D22,Bank_Data!L2:L1001)
D23: 33 | E23: =AVERAGEIF(Bank_Data!E2:E1001,D23,Bank_Data!L2:L1001)
D24: 34 | E24: =AVERAGEIF(Bank_Data!E2:E1001,D24,Bank_Data!L2:L1001)
D25: 35 | E25: =AVERAGEIF(Bank_Data!E2:E1001,D25,Bank_Data!L2:L1001)
D26: 36 | E26: =AVERAGEIF(Bank_Data!E2:E1001,D26,Bank_Data!L2:L1001)
D27: 37 | E27: =AVERAGEIF(Bank_Data!E2:E1001,D27,Bank_Data!L2:L1001)
D28: 38 | E28: =AVERAGEIF(Bank_Data!E2:E1001,D28,Bank_Data!L2:L1001)
D29: 39 | E29: =AVERAGEIF(Bank_Data!E2:E1001,D29,Bank_Data!L2:L1001)
D30: 40 | E30: =AVERAGEIF(Bank_Data!E2:E1001,D30,Bank_Data!L2:L1001)
D31: 41 | E31: =AVERAGEIF(Bank_Data!E2:E1001,D31,Bank_Data!L2:L1001)
D32: 42 | E32: =AVERAGEIF(Bank_Data!E2:E1001,D32,Bank_Data!L2:L1001)
D33: 43 | E33: =AVERAGEIF(Bank_Data!E2:E1001,D33,Bank_Data!L2:L1001)
D34: 44 | E34: =AVERAGEIF(Bank_Data!E2:E1001,D34,Bank_Data!L2:L1001)
D35: 45 | E35: =AVERAGEIF(Bank_Data!E2:E1001,D35,Bank_Data!L2:L1001)
D36: 46 | E36: =AVERAGEIF(Bank_Data!E2:E1001,D36,Bank_Data!L2:L1001)
D37: 47 | E37: =AVERAGEIF(Bank_Data!E2:E1001,D37,Bank_Data!L2:L1001)
D38: 48 | E38: =AVERAGEIF(Bank_Data!E2:E1001,D38,Bank_Data!L2:L1001)
D39: 49 | E39: =AVERAGEIF(Bank_Data!E2:E1001,D39,Bank_Data!L2:L1001)
D40: 50 | E40: =AVERAGEIF(Bank_Data!E2:E1001,D40,Bank_Data!L2:L1001)
D41: 51 | E41: =AVERAGEIF(Bank_Data!E2:E1001,D41,Bank_Data!L2:L1001)
D42: 52 | E42: =AVERAGEIF(Bank_Data!E2:E1001,D42,Bank_Data!L2:L1001)
D43: 53 | E43: =AVERAGEIF(Bank_Data!E2:E1001,D43,Bank_Data!L2:L1001)
...

Sheet Project_Notes
A1: PROJECT GUIDE
A3: 1. Bank_Data contains the working bank churn dataset.
A4: 2. Dashboard contains KPI formulas and the required Excel graphs.
A5: 3. Churn Rate = Average of Exited because Exited is coded 1 = churned and 0 = retained.
A6: 4. Use the Dashboard charts for your Excel section of the project.
A7: 5. For SQL, import the Bank_Data sheet into your SQL database.
A8: 6. For Python/ML, use the same Bank_Data data and predict Exited.
A9: 7. For Power BI, import Bank_Data plus your ML prediction output.
